Workbook

Sheet INFO liveLog
A1: Date | B1: comment
A2: 44958 | B2: Anne, Bennet and Paul met for discussions; protocol is linked
A3: 08.08.2023 | B3: Bill and Paul packed samples at ARI, Inuvik
A4: 11.08.2023 | B4: - in blue container on Donovan Archie's lot, there are four Thermoboxes: 7363 - empty (had contained 60 sets, probably now on ARI loading dock in medium Zarges box) 7183 - empty (had contained 74 sets, probably now on ARI loading dock in medium Zarges box) 7373 - 45 sample sets including nutrients 7368 - 59 sample sets including nutrients
A5: 15.08.2023 | B5: Samples landed with Bill in Germany but luggage and samples got lost
A6: 18.08.2023 | B6: Samples got found at BER and arrived at AWI, were stored in +4 degree room
A7: 21.08.2023 | B7: Samples were unpacked and listed by Antje and Caroline. Filter and nutrients back to freezer. CDOM, DOC to +4 room.
A8: 22.08.2023 | B8: Restsample was measured for pH and EC with robot and cations and anions bottles were prepared
A10: 01.09.2023 | B10: ich habe mit Lisa Bröder (cc) bezüglich der Filter gesprochen, wie wir damit weiter umgehen sollen. Wir haben beschlossen, dass wir sie bei uns trocknen ( ganz normal 24h, ~60°C, aufpassen mit Staub--> Petrischalendeckel offen drauflegen) und fuer SPM einwiegen, und die Filter dann getrocknet zur ETH schicken. Dies hat auch den Vorteil, dass der Transport einfacher ist. Dort werden sie dann auf d13C, d14C und evtl ausgewählte Filter auf Biomarker (hängt von Materialmenge ab) gemessen. Parallel versuche ich mal mit Martin Hieronymi zu sprechen, ob sie am Hereon evtl Kapazität haben zum POC concentration messen (oder können wir das iwo hier auf dem Berg?). POC concentration ist an der ETH Teil von einer Serie an Messungen (e.g. d14c) und dauert daher ziemlich lange (langer Probenrückstau) und ist aufwändig. Zunächst würde ich vorschlagen, dass Felica die Filter trocknet und einwiegt sobald sie wieder aus dem Urlaub zurück ist. Sagst du uns bescheid Felica? @Lisa, wenn zb POC am Hereon gemessen wird (ich vermute es wird ein Teil vom Filter herausgestanzt?), beeinträchtigt dies nicht die möglichkeiten zur d14C, d13C messung?
A11: 04.09.2023 | B11: CDOM was measured by Felica at GFZ using 5cm cuvettes
A12: 05.09.2023 | B12: Filters were thawed and put to drying oven by Felica
A13: 07.09.2023 | B13: Filters were weighted by Felica
A14: 26.09.2023 | B14: DOC/TDN were measured by Antje
A15: 16.10.2023 | B15: Cations were measured by Antje
... A34: 26.09.2024 | B34: Filters (#36 to #60, Peel River samples, blanks) were weighted by Caroline and Felica, left in desiccator (FG)
A35: 45627 | B35: CDOM (#36 to #60, Peel River samples, FLOCHAR) were measured by Daniela, Annabeth, Bennet and Felica (FG)
A36: 45658 | B36: Restsample (#36 to #60, Pauls River samples, blanks) were thawed , Filtration (0,45µm CA-Filter), Separation, Conservation_ anions/cations on thawed Restsample , Restsample was measured for pH and EC with robot (ca.30ml), no Restsample left (Caroline)
A37: 45658 | B37: DOC/TDN (#36 to #60, Pauls River samples, blanks) were measured by Antje
A38: 03.02.2025 | B38: Bennet added DOC/TDN data to this table
A39: 45658 | B39: BJ has talked to Fre and Bill aboiut sample transport from Inuvik to GER
A40: 45689 | B40: 2 yeti boxes sent with thinice freight to inuvik
A41: 45689 | B41: anions/cations(#36 to #60, Pauls River samples, blanks) were measured by Antje&Caroline
A42: 08.05.2025 | B42: Marie and Felica listed and sorted new water samples and filter (#61-#75) and two ARI ice cores -> Laborkühlschrank R004 (cooled)/ RUG05 (frozen, Freezer 3, Truhe)
A43: 16.05.2025 | B43: Marie put Rest samples (#61-#75) in Laborkühlschrank in R004 (Geochemie)
A44: 19.05.2025 | B44: Restsample (#61 to #75) were thawed , Filtration (0,45µm CA-Filter), Separation, Conservation_ anions/cations on thawed Restsample , Restsample was measured for pH and EC with robot (ca.30ml), no Restsample left (Caroline/Inka/Antje)
A45: 26.05.2025 | B45: Marie added raw data (incl. DL) values of iones to DUCCEM_full_cations+anions (till #60)
A46: 05.06.2025 | B46: Marie added final results up till #60 (iones, isotopes incl. deviation, POC) + a new column for ice thickness
A47: 11.06.2025 | B47: Marie added iones+Leitfaehigkeit up to #75 in liveRESULTS and full_cationes+aniones
A48: 19.06.2025 | B48: Order of CDOM data ID50 to 60 was wrong --> MJ corrected, MJ added CDOM 61-75
A49: 03.07.2025 | B49: SPM Filter #61 to #75 put to drying oven by Marie and Felica (50 degrees)
A50: 07.07.2025 | B50: SPM Filter #61 to #75 were weighed back by Marie and Felica
A51: 10.07.2025 | B51: Marie, Paul, Bennet and Felica updated the layout of liveResults and Marie added new tables that are needed for the dashboard (Parameter_Info, Discharge_Gauge)

Sheet Parameter_Info
A1: Name | B1: For Timeseries | C1: For Scatter | D1: Renamed (unit) | E1: Info
A2: {=TRANSPOSE(DUCCEM_liveResults!A1:BF1)} -> ID | B2: No | C2: No | D2: ID | E2: Running number for samples
A3: Date | B3: On x-axis by default | C3: No | D3: Datetime, local (YYYY-MM-DD) | E3: Local date (Inuvik, NWT, Canada)
A4: Time local (hh:mm) | B4: No | C4: No | D4: Time (hh:mm) | E4: Local time (Inuvik, NWT, Canada)
A5: Lat (DecDeg) | B5: No | C5: No | D5: Lat (DecDeg)
A6: Lon (DecDeg) | B6: No | C6: No | D6: Lon (DecDeg)
A7: comments on sampling location | B7: No | C7: No | D7: comments on sampling location
A8: comments on sampling situation | B8: No | C8: No | D8: comments on sampling situation
A9: sampled by | B9: No | C9: No | D9: sampled by
A10: Temperature in situ (°C) | B10: Yes | C10: Yes | D10: Water temperature (°C) | E10: The in situ river temperature was measured using a SonTek CastAway-CTD is a compact, GPS-enabled instrument that measures conductivity, temperature, and depth with high accuracy (±0.05 °C for temperature, ±0.25% for pressure and conductivity). It features a 5 Hz sampling rate
A11: Electrical Conductivity in situ (µS cm⁻¹) | B11: Yes | C11: Yes | D11: Electrical Conductivity, in situ (µS cm⁻¹) | E11: The in situ river electrical conductivity was measured using a SonTek CastAway-CTD is a compact, GPS-enabled instrument that measures conductivity, temperature, and depth with high accuracy (±0.05 °C for temperature, ±0.25% for pressure and conductivity). It features a 5 Hz sampling rate
A12: Electrical Conductivity Lab (µS cm⁻¹) | B12: Yes | C12: Yes | D12: Electrical Conductivity, Lab (µS cm⁻¹) | E12: For the pH/EC measurement the original frozen, unfiltered sample is thawed and then measured. A pH EC AR Robot from Seal Analytical is used for the measurement in combination with a Thermo Scientific Versa Star Pro Meter and a pH electrode (Thermo Scientific Orion) and a Conductivity electrode (Dura Probe 4 - Electrode Conductivity Cell) with a measuring range of 1 µS/cm to 200 mS/cm. A three-point calibration is performed for pH measurement.
A13: pH Lab (-) | B13: Yes | C13: Yes | D13: pH, Lab (-) | E13: For the pH/EC measurement the original frozen, unfiltered sample is thawed and then measured. A pH EC AR Robot from Seal Analytical is used for the measurement in combination with a Thermo Scientific Versa Star Pro Meter and a pH electrode (Thermo Scientific Orion) and a Conductivity electrode (Dura Probe 4 - Electrode Conductivity Cell) with a measuring range of 1 µS/cm to 200 mS/cm. A three-point calibration is performed for pH measurement.
A14: Discharge in situ (m³ s⁻¹) | B14: No | C14: No | D14: Discharge, in situ (m³ s⁻¹)
A15: δ18O (‰) | B15: Yes | C15: Yes | D15: δ18O (‰) | E15: Oxygen (δ¹⁸O) and hydrogen (δD) isotope measurements conducted at the ISOLAB Facility at the Alfred Wegener Institute (AWI) Potsdam using DELTA-S Finnigan MAT mass spectrometers (USA) employing the equilibration method, described in Meyer et al. (2000). The isotope ratios are reported in per mil (‰) relative to the Vienna Standard Mean Ocean Water (VSMOW) as the international reference standard. Isotope analyses at ETH Zurich were performed using a PICARRO isotope and gas concentration analyzer (L2130-i). Nitrogen was used as purge gas and the vaporizer temperature was set at 110 °C. There were 12 injections per sample (1.8 µL), six injections were used to flush the vaporizer and measurement cavity of the instrument between samples. The latter six injections were injected as individual pulses for measurement with the latter four used in the data reduction. Isotope compositions were calibrated against reference materials from the International Atomic Energy Agency (IAEA) including SLAP2, GRESP, and VSMOW2 and in-house reference materials, resulting in a precision of analyses of 0.1 – 2‰. An independent quality control was carried up against reference materials from the United States Geologic Survey (USGS) which were run as quality control.
A16: δD (‰) | B16: Yes | C16: Yes | D16: δD (‰) | E16: Oxygen (δ¹⁸O) and hydrogen (δD) isotope measurements conducted at the ISOLAB Facility at the Alfred Wegener Institute (AWI) Potsdam using DELTA-S Finnigan MAT mass spectrometers (USA) employing the equilibration method, described in Meyer et al. (2000). The isotope ratios are reported in per mil (‰) relative to the Vienna Standard Mean Ocean Water (VSMOW) as the international reference standard. Isotope analyses at ETH Zurich were performed using a PICARRO isotope and gas concentration analyzer (L2130-i). Nitrogen was used as purge gas and the vaporizer temperature was set at 110 °C. There were 12 injections per sample (1.8 µL), six injections were used to flush the vaporizer and measurement cavity of the instrument between samples. The latter six injections were injected as individual pulses for measurement with the latter four used in the data reduction. Isotope compositions were calibrated against reference materials from the International Atomic Energy Agency (IAEA) including SLAP2, GRESP, and VSMOW2 and in-house reference materials, resulting in a precision of analyses of 0.1 – 2‰. An independent quality control was carried up against reference materials from the United States Geologic Survey (USGS) which were run as quality control.
A17: D - excess (‰) | B17: Yes | C17: Yes | D17: D excess (‰) | E17: Deuterium excess (d) was calculated according to the equation (after Dansgaard, 1964): d = δD − 8 × δ¹⁸O
A18: Ice Thickness in situ (cm) | B18: Yes | C18: Yes | D18: Ice thickness, in situ (cm) | E18: Ice thickness was measured after drilling the ice hole with a special ice thickness measureing tape
A19: SPM (mg L⁻¹) | B19: Yes | C19: Yes | D19: SPM concentration (mg L⁻¹) | E19: Suspended sediment concentration - weighted particles on filter
A20: POC (mg L⁻¹) | B20: Yes | C20: Yes | D20: POC (mg L⁻¹) | E20: Particulate organic carbon concentration in mg per liter. Measured on an elemental analyzer and corrected for blank, size and drift of the instrument
A21: POC (%) | B21: Yes | C21: Yes | D21: POC (%) | E21: Particulate organic carbon relative proportion. Percentage of organic carbon in the sample. Measured on an elemental analyzer and corrected for blank, size and drift of the instrument
A22: d13C (‰) | B22: Yes | C22: Yes | D22: δ13C (‰) | E22: Stable organic carbon isotope ratios. Measured on an elemental analyzer coupled with an isotope ratio mass spectrometer. Corrected for size, blank and drift, normalized to international standards (USGS64 and EDTA)
A23: aCDOM(254) (m⁻¹) | B23: Yes | C23: Yes | D23: CDOM absorption at 254 nm (m⁻¹) | E23: For CDOM absorption, the sample was filtered through a 0.45 μm cellulose acetate filter (Whatman GF/F syringe filter) which had been rinsed with 50 mL sample water. CDOM samples were collected in pre-rinsed 100 mL amber glass bottles that were stored in the dark at 4°C until analysis. aCDOM was measured at the German Research Center for Geosciences (GFZ), Potsdam, Germany using a double beam LAMBDA 950 UV/Vis (PerkinElmer) spectrophotometer. The absorbance (A) was measured between 200 and 750 nm in 1 nm steps using a 5 cm or 10 cm cuvette, depending on the expected concentration of dissolved organic matter. Absorption (a) was calculated from the resulting absorbance measurements via aCDOM(λ) = 2.303 * A(λ) * l, where l is the path length (length of cuvette in meter). Every 5 to 10 samples, the reference sample (Milli-Q water) was exchanged and a blank was measured to avoid instrument drift.
A24: aCDOM(443) (m⁻¹) | B24: No | C24: No | D24: CDOM absorption at 443 nm (m⁻¹) | E24: For CDOM absorption, the sample was filtered through a 0.45 μm cellulose acetate filter (Whatman GF/F syringe filter) which had been rinsed with 50 mL sample water. CDOM samples were collected in pre-rinsed 100 mL amber glass bottles that were stored in the dark at 4°C until analysis. aCDOM was measured at the German Research Center for Geosciences (GFZ), Potsdam, Germany using a double beam LAMBDA 950 UV/Vis (PerkinElmer) spectrophotometer. The absorbance (A) was measured between 200 and 750 nm in 1 nm steps using a 5 cm or 10 cm cuvette, depending on the expected concentration of dissolved organic matter. Absorption (a) was calculated from the resulting absorbance measurements via aCDOM(λ) = 2.303 * A(λ) * l, where l is the path length (length of cuvette in meter). Every 5 to 10 samples, the reference sample (Milli-Q water) was exchanged and a blank was measured to avoid instrument drift.
A25: S275-295 (nm⁻¹) | B25: Yes | C25: Yes | D25: S275-295 (nm⁻¹) | E25: S275–295 was calculated by fitting a regression for the wavelength ranges 275–295 nm to the exponential function (Helms et al., 2008)
A26: S350-400 (nm⁻¹) | B26: Yes | C26: Yes | D26: S350-400 (nm⁻¹) | E26: S350-400 was calculated by fitting a regression for the wavelength ranges 275–295 nm to the exponential function (Helms et al., 2008)
... A63: Discharge | B63: Yes | C63: Yes | D63: Discharge (m³ s⁻¹) | E63: Discharge data is taken from ArcticGRO (Shiklomanov et al. 2021).

Sheet DUCCEM_liveResults
A1: ID | B1: Date | C1: Time local (hh:mm) | D1: Lat (DecDeg) | E1: Lon (DecDeg) | F1: comments on sampling location | G1: comments on sampling situation | H1: sampled by | I1: Temperature in situ (°C) | J1: Electrical Conductivity in situ (µS cm⁻¹) | K1: Electrical Conductivity Lab (µS cm⁻¹) | L1: pH Lab (-) | M1: Discharge in situ (m³ s⁻¹) | N1: δ18O (‰) | O1: δD (‰) | P1: D - excess (‰) | Q1: Ice Thickness in situ (cm) | R1: SPM (mg L⁻¹) | S1: POC (mg L⁻¹) | T1: POC (%) | U1: d13C (‰) | V1: aCDOM(254) (m⁻¹) | W1: aCDOM(443) (m⁻¹) | X1: S275-295 (nm⁻¹) | Y1: S350-400 (nm⁻¹) | Z1: Slope Ratio (-) | AA1: SUVA (m⁻²gC⁻¹) | AB1: DOC (mg L⁻¹) | AC1: TDN (mg L⁻¹) | AD1: Al (µg L⁻¹) | AE1: Ba (µg L⁻¹) | AF1: Ca (µg L⁻¹) | AG1: Fe (µg L⁻¹) | AH1: K (mg L⁻¹) | AI1: Mg (mg L⁻¹) | AJ1: Mn (µg L⁻¹) | AK1: Na (mg L⁻¹) | AL1: P (mg L⁻¹) | AM1: Si (mg L⁻¹) | AN1: Sr (µg L⁻¹) | AO1: Pb (µg L⁻¹) | AP1: Cr (µg L⁻¹) | AQ1: V (µg L⁻¹) | AR1: Co (µg L⁻¹) | AS1: Ni (µg L⁻¹) | AT1: Cu (µg L⁻¹) | AU1: Zn (µg L⁻¹) | AV1: F (mg L⁻¹) | AW1: Cl (mg L⁻¹) | AX1: SO4 (mg L⁻¹) | AY1: Br (mg L⁻¹) | AZ1: NO3 (mg L⁻¹) | BA1: PO4 (mg L⁻¹) | BB1: NO3, nutrients (µmol L⁻¹) | BC1: NO2, nutrients (µmol/L) | BD1: PO4, nutrients (µmol/L) | BE1: Si, nutrients (µmol/L) | BF1: NH4, nutrients (µmol/L)
A2: 1 | B2: 45050 | C2: 0.625 | D2: 68.338 | E2: -133.7063 | F2: from ice_ 20 m from land_ 108 cm thick ice | G2: frozen river_ clear colourless H2O | H2: Lance Gray | I2: 0.23 | J2: 366 | K2: 342.38 | N2: -18.42 | O2: -149.8 | P2: -2.4 | Q2: 108 | R2: =DUCCEM_full_SPM!K2 -> 11.166667 | S2: 0.19 | T2: 1.71 | U2: -30.9 | V2: =DUCCEM_full_CDOM!BM2:BM116 -> 25.14337 | W2: 0.81669 | X2: =DUCCEM_full_CDOM!WN2 -> 0.02081 | Y2: =DUCCEM_full_CDOM!WO2 -> 0.01879 | Z2: =DUCCEM_full_CDOM!WP2 -> 1.1075 | AA2: =(V2/2.303)/AB2 -> 2.3994856 | AB2: 4.55 | AC2: 0.39 | AD2: < 20 | AE2: 53 | AF2: 39.6 | AG2: < 20 | AH2: 1.05 | AI2: 11.1 | AJ2: < 20 | AK2: 13.2 | AL2: < 0.10 | AM2: 2.04 | AN2: 279 | AO2: < 25 | AP2: < 20 | AQ2: < 20 | AR2: < 20 | AS2: < 20 | AT2: < 20 | AU2: < 20 | AV2: 0.09 | AW2: 15.2 | AX2: 46.3 | AY2: < 0.05 | AZ2: 0.52 | BA2: < 0.10 | BB2: 10.633 | BC2: 0.034 | BD2: 0.136 | BE2: 71.756 | BF2: 0.176
A3: TSI | B3: 45051 | C3: 0.5 | D3: 67.4543 | E3: -133.7178 | F3: from ice_ middle of Mackenzie River at Arctic Red River = location of ArcticGRO sampling | G3: frozen river_ clear colourless H2O | H3: Anne Morgenstern_ Felica Gehde | I3: 0.1 | J3: 358 | K3: 329.27 | N3: -18.35 | O3: -149 | P3: -2.2 | R3: =DUCCEM_full_SPM!K3 -> 6.7 | S3: 0.1 | T3: 1.47 | U3: -30.82 | V3: =DUCCEM_full_CDOM!BM3:BM117 -> 24.4603 | W3: 0.862335 | X3: =DUCCEM_full_CDOM!WN3 -> 0.0209 | Y3: =DUCCEM_full_CDOM!WO3 -> 0.01829 | Z3: =DUCCEM_full_CDOM!WP3 -> 1.1427 | AA3: =(V3/2.303)/AB3 -> 2.4585786 | AB3: 4.32 | AC3: 0.36 | AD3: < 20 | AE3: 51 | AF3: 36.7 | AG3: < 20 | AH3: 1.06 | AI3: 10.7 | AJ3: < 20 | AK3: 12.8 | AL3: < 0.10 | AM3: 1.99 | AN3: 272 | AO3: < 25 | AP3: < 20 | AQ3: < 20 | AR3: < 20 | AS3: < 20 | AT3: < 20 | AU3: < 20 | AV3: 0.09 | AW3: 14.4 | AX3: 44.1 | AY3: < 0.05 | AZ3: 0.47 | BA3: < 0.10 | BB3: 9.713 | BC3: 0.024 | BD3: 0.081 | BE3: 69.861 | BF3: 0.028
A4: blank 1 | B4: 45051 | H4: Felica Gehde
A5: 2 | B5: 45051 | C5: 0.64583333 | D5: 68.338 | E5: -133.7063 | F5: from ice_ 20 m from land_ 108 cm thick ice | G5: frozen river; wood particles from marking twig fell into hole_ removed as good as possible | H5: Anne Morgenstern_ Felica Gehde | I5: 0.13 | J5: 371 | K5: 332.97 | N5: -18.38 | O5: -149 | P5: -2 | Q5: 108 | R5: =DUCCEM_full_SPM!K5 -> 2.2857143 | S5: 0.07 | T5: 3.02 | U5: -33.41 | V5: =DUCCEM_full_CDOM!BM5:BM119 -> 24.49701 | W5: 0.835989 | X5: =DUCCEM_full_CDOM!WN5 -> 0.02088 | Y5: =DUCCEM_full_CDOM!WO5 -> 0.01863 | Z5: =DUCCEM_full_CDOM!WP5 -> 1.1208 | AA5: =(V5/2.303)/AB5 -> 2.4565819 | AB5: 4.33 | AC5: 0.32 | AD5: < 20 | AE5: 51 | AF5: 37.8 | AG5: < 20 | AH5: 1.07 | AI5: 11.1 | AJ5: < 20 | AK5: 13.1 | AL5: < 0.10 | AM5: 2.05 | AN5: 273 | AO5: < 25 | AP5: < 20 | AQ5: < 20 | AR5: < 20 | AS5: < 20 | AT5: < 20 | AU5: < 20 | AV5: 0.1 | AW5: 15.2 | AX5: 46.2 | AY5: < 0.05 | AZ5: 0.52 | BA5: < 0.10
A6: 3 | B6: 45054 | C6: 0.45833333 | D6: 68.338 | E6: -133.7063 | F6: from ice_ same hole as for sample number 002 | G6: frozen river; very wet snow and standing meltwater on the ice; 3 CTD casts_ use last one only! | H6: Anne Morgenstern_ Felica Gehde | I6: 0.11 | J6: 371 | K6: 333.27 | N6: -18.43 | O6: -148.5 | P6: -1.1 | R6: =DUCCEM_full_SPM!K6 -> 2.3 | S6: 0.08 | T6: 3.68 | U6: -32.93 | V6: =DUCCEM_full_CDOM!BM6:BM120 -> 24.40954 | W6: 0.824244 | X6: =DUCCEM_full_CDOM!WN6 -> 0.02068 | Y6: =DUCCEM_full_CDOM!WO6 -> 0.01884 | Z6: =DUCCEM_full_CDOM!WP6 -> 1.0977 | AA6: =(V6/2.303)/AB6 -> 2.392555 | AB6: 4.43 | AC6: 0.34 | AD6: < 20 | AE6: 52 | AF6: 38.3 | AG6: < 20 | AH6: 1.09 | AI6: 11.4 | AJ6: < 20 | AK6: 13.4 | AL6: < 0.10 | AM6: 2.09 | AN6: 278 | AO6: < 25 | AP6: < 20 | AQ6: < 20 | AR6: < 20 | AS6: < 20 | AT6: < 20 | AU6: < 20 | AV6: 0.09 | AW6: 15.1 | AX6: 46.1 | AY6: < 0.05 | AZ6: 0.55 | BA6: < 0.10 | BB6: 10.314 | BC6: 0.019 | BD6: 0.084 | BE6: 67.018 | BF6: 0.003
A7: 4 | B7: 45055 | C7: 0.41666667 | D7: 68.338 | E7: -133.7063 | F7: on ice_ 13 cm of meltwater on ice_ ice thickness 96.5 cm | G7: spring melt on ice_ cloudy_ little wind_ little colour to water_ 2 CTD casts - use 2nd one | H7: Lance Gray | I7: 0.13 | J7: 371 | K7: 338.98 | N7: -18.4 | O7: -149.1 | P7: -1.8 | Q7: 96.5 | R7: =DUCCEM_full_SPM!K7 -> 2.4 | S7: 0.09 | T7: 3.81 | U7: -33.72 | V7: =DUCCEM_full_CDOM!BM7:BM121 -> 24.9373 | W7: 0.916318 | X7: =DUCCEM_full_CDOM!WN7 -> 0.0204 | Y7: =DUCCEM_full_CDOM!WO7 -> 0.01889 | Z7: =DUCCEM_full_CDOM!WP7 -> 1.0799 | AA7: =(V7/2.303)/AB7 -> 2.4062624 | AB7: 4.5 | AC7: 0.36 | AD7: < 20 | AE7: 54 | AF7: 39.6 | AG7: < 20 | AH7: 1.06 | AI7: 11.3 | AJ7: < 20 | AK7: 13.2 | AL7: < 0.10 | AM7: 2.08 | AN7: 288 | AO7: < 25 | AP7: < 20 | AQ7: < 20 | AR7: < 20 | AS7: < 20 | AT7: < 20 | AU7: < 20 | AV7: 0.1 | AW7: 15.1 | AX7: 46.3 | AY7: < 0.05 | AZ7: 0.51 | BA7: < 0.10 | BB7: 10.017 | BC7: 0.022 | BD7: 0.137 | BE7: 68.305 | BF7: 0.025
A8: 5 | B8: 45056 | C8: 0.41666667 | D8: 68.338 | E8: -133.7063 | F8: from ice_ same hole as last days | G8: standing meltwater puddle from shore reaches to ice hole | H8: Anne Morgenstern_ Felica Gehde | I8: 0.16 | J8: 367 | K8: 344.89 | N8: -18.4 | O8: -149.1 | P8: -1.9 | R8: =DUCCEM_full_SPM!K8 -> 2.5 | S8: 0.08 | T8: 3.23 | U8: -33.49 | V8: =DUCCEM_full_CDOM!BM8:BM122 -> 24.83205 | W8: 1.028566 | X8: =DUCCEM_full_CDOM!WN8 -> 0.02023 | Y8: =DUCCEM_full_CDOM!WO8 -> 0.01803 | Z8: =DUCCEM_full_CDOM!WP8 -> 1.122 | AA8: =(V8/2.303)/AB8 -> 2.4787309 | AB8: 4.35 | AC8: 0.35 | AD8: < 20 | AE8: 57 | AF8: 40.9 | AG8: < 20 | AH8: 1.08 | AI8: 11.3 | AJ8: < 20 | AK8: 13.2 | AL8: < 0.10 | AM8: 2.06 | AN8: 295 | AO8: < 25 | AP8: < 20 | AQ8: < 20 | AR8: < 20 | AS8: < 20 | AT8: < 20 | AU8: < 20 | AV8: 0.09 | AW8: 15.2 | AX8: 46.5 | AY8: < 0.05 | AZ8: 0.52 | BA8: < 0.10
A9: 6 | B9: 45062 | C9: 0.38888889 | F9: sampling from shore; 15 m of exposed river on edge_ candle ice in the center; 2 CTD casts thrown as close to the ice as possible_ CTD touched riverbed and dragged along it in retrieval | G9: spring melt_ 2 days of 20 °C prior to today_ muddy water_ lots of sediment suspended_ wind blowing up river | H9: Lance Gray_ Greg Elias | I9: 0.11 | J9: 311 | K9: 286.51 | N9: -19.25 | O9: -154.8 | P9: -0.8 | R9: =DUCCEM_full_SPM!K9 -> 60 | S9: 0.83 | T9: 1.38 | U9: -29.64 | V9: =DUCCEM_full_CDOM!BM9:BM123 -> 37.55129 | W9: 1.929453 | X9: =DUCCEM_full_CDOM!WN9 -> 0.01699 | Y9: =DUCCEM_full_CDOM!WO9 -> 0.01721 | Z9: =DUCCEM_full_CDOM!WP9 -> 0.9872 | AA9: =(V9/2.303)/AB9 -> 2.9754343 | AB9: 5.48 | AC9: 0.32 | AD9: < 20 | AE9: 46 | AF9: 34.1 | AG9: < 20 | AH9: 1.04 | AI9: 9.5 | AJ9: < 20 | AK9: 10.7 | AL9: < 0.10 | AM9: 1.69 | AN9: 231 | AO9: < 25 | AP9: < 20 | AQ9: < 20 | AR9: < 20 | AS9: < 20 | AT9: < 20 | AU9: < 20 | AV9: 0.09 | AW9: 11.4 | AX9: 40.7 | AY9: < 0.05 | AZ9: 0.37 | BA9: < 0.10
A10: 7 | B10: 45069 | C10: 0.41666667 | D10: 68.3383 | E10: -133.705 | F10: hand taken with bottle_ sample taken upriver of myself ~15 m into water_ stood still for ~1 min to let water settle | G10: spring breakup of ice one day prior_ beavers swimming by slopping water_ lots of sediment_ still ice chunks and floating logs_ could not reach point of previous sample | H10: Lance Gray | I10: 0.75 | J10: 229 | K10: 218.01 | N10: -20.08 | O10: -160.4 | P10: 0.2 | R10: =DUCCEM_full_SPM!K10 -> 197 | S10: 2.41 | T10: 1.22 | U10: -27.88 | V10: =DUCCEM_full_CDOM!BM10:BM124 -> 59.12229 | W10: 3.082565 | X10: =DUCCEM_full_CDOM!WN10 -> 0.01526 | Y10: =DUCCEM_full_CDOM!WO10 -> 0.01742 | Z10: =DUCCEM_full_CDOM!WP10 -> 0.876 | AA10: =(V10/2.303)/AB10 -> 3.347048 | AB10: 7.67 | AC10: 0.37 | AD10: 26 | AE10: 51 | AF10: 28.2 | AG10: 34 | AH10: 0.89 | AI10: 7.19 | AJ10: 28 | AK10: 5.66 | AL10: < 0.10 | AM10: 1.2 | AN10: 154 | AO10: < 25 | AP10: < 20 | AQ10: < 20 | AR10: < 20 | AS10: < 20 | AT10: < 20 | AU10: < 20 | AV10: 0.07 | AW10: 4.62 | AX10: 28.8 | AY10: < 0.05 | AZ10: 0.23 | BA10: < 0.10
A11: blank 2 | B11: 45069 | H11: Lance Gray
A12: 8 | B12: 45072 | C12: 0.45138889 | F12: waded into water ~15 m for sample by hand; no ice on near side of river_ a little ice floating down river | G12: spring high water_ little wind_ calm water flowing; lots of sediment suspended_ some floating debris (branches_ ???_ etc.)_ muskrats swimming nearby | H12: Lance Gray | I12: 2.71 | J12: 211 | K12: 200.48 | N12: -20.59 | O12: -164.2 | P12: 0.6 | R12: =DUCCEM_full_SPM!K12 -> 66 | S12: 1.12 | T12: 1.7 | U12: -29.2 | V12: =DUCCEM_full_CDOM!BM12:BM126 -> 96.04887 | W12: 5.960302 | X12: =DUCCEM_full_CDOM!WN12 -> 0.01434 | Y12: =DUCCEM_full_CDOM!WO12 -> 0.01638 | Z12: =DUCCEM_full_CDOM!WP12 -> 0.8755 | AA12: =(V12/2.303)/AB12 -> 3.595343 | AB12: 11.6 | AC12: 0.46 | AD12: < 20 | AE12: 44 | AF12: 25.3 | AG12: 73 | AH12: 1.09 | AI12: 6.83 | AJ12: 46 | AK12: 5.67 | AL12: < 0.10 | AM12: 1.12 | AN12: 137 | AO12: < 25 | AP12: < 20 | AQ12: < 20 | AR12: < 20 | AS12: < 20 | AT12: < 20 | AU12: < 20 | AV12: 0.08 | AW12: 4.67 | AX12: 27.6 | AY12: < 0.05 | AZ12: 0.16 | BA12: < 0.10
A13: 9 | B13: 45076 | C13: 0.46527778 | F13: sample taken from shoreline_ very deep mud left to settle before taking sample | G13: spring flood levels settling_ little wind_ lots of sediment_ floating debris | H13: Lance Gray | I13: 5.76 | J13: 226 | K13: 217.11 | N13: -20.43 | O13: -163.1 | P13: 0.3 | R13: =DUCCEM_full_SPM!K13 -> 46 | S13: 0.89 | T13: 1.93 | U13: -29.17 | V13: =DUCCEM_full_CDOM!BM13:BM127 -> 77.71976 | W13: 4.403981 | X13: =DUCCEM_full_CDOM!WN13 -> 0.01503 | Y13: =DUCCEM_full_CDOM!WO13 -> 0.01678 | Z13: =DUCCEM_full_CDOM!WP13 -> 0.8957 | AA13: =(V13/2.303)/AB13 -> 3.4971173 | AB13: 9.65 | AC13: 0.46 | AD13: < 20 | AE13: 49 | AF13: 28.7 | AG13: 42 | AH13: 1.04 | AI13: 7.58 | AJ13: 38 | AK13: 6.71 | AL13: < 0.10 | AM13: 1.27 | AN13: 158 | AO13: < 25 | AP13: < 20 | AQ13: < 20 | AR13: < 20 | AS13: < 20 | AT13: < 20 | AU13: < 20 | AV13: 0.08 | AW13: 5.78 | AX13: 29.4 | AY13: < 0.05 | AZ13: 0.17 | BA13: < 0.10 | BB13: 3.245 | BC13: 0.06 | BD13: 0.12 | BE13: 42.895 | BF13: 0.01
A14: 10 | B14: 45083 | C14: 0.56597222 | F14: from shoreline_ by hand_ standing on river edge letting sediment settle before sample | G14: lowering water level_ up river wind - light_ lots of sediment visible_ difficult to have zero disturbance in sediment but best efforts made to gather 'clean' sample | H14: Lance Gray | I14: 10.33 | J14: 232 | K14: 221.91 | N14: -20.19 | O14: -160.9 | P14: 0.7 | R14: =DUCCEM_full_SPM!K14 -> 58.5 | S14: 0.87 | T14: 1.48 | U14: -30.21 | V14: =DUCCEM_full_CDOM!BM14:BM128 -> 72.3598 | W14: 3.879265 | X14: =DUCCEM_full_CDOM!WN14 -> 0.01546 | Y14: =DUCCEM_full_CDOM!WO14 -> 0.01711 | Z14: =DUCCEM_full_CDOM!WP14 -> 0.9036 | AA14: =(V14/2.303)/AB14 -> 3.3178247 | AB14: 9.47 | AC14: 0.42 | AD14: < 20 | AE14: 49 | AF14: 27.8 | AG14: 33 | AH14: 1 | AI14: 7.79 | AJ14: 35 | AK14: 6.64 | AL14: < 0.10 | AM14: 1.4 | AN14: 154 | AO14: < 25 | AP14: < 20 | AQ14: < 20 | AR14: < 20 | AS14: < 20 | AT14: < 20 | AU14: < 20 | AV14: 0.07 | AW14: 5.82 | AX14: 30.4 | AY14: < 0.05 | AZ14: 0.16 | BA14: < 0.10
A15: Transect bottle #1 | B15: 45086 | F15: transect taken across width of river at same point of other samples; #1 taken closest to sample side of river | H15: technicians; filtering by Lance Gray | R15: =DUCCEM_full_SPM!K15 -> 33.5 | S15: 0.57 | T15: 1.71 | U15: -30.57
A16: Transect bottle #2 | B16: 45086 | F16: transect taken across width of river at same point of other samples; #2 taken in middle of river | H16: technicians; filtering by Lance Gray | R16: =DUCCEM_full_SPM!K16 -> 46.5 | S16: 0.62 | T16: 1.33 | U16: -29.01
A17: Transect bottle #3 | B17: 45086 | F17: transect taken across width of river at same point of other samples; #3 taken opposite side of river | H17: technicians; filtering by Lance Gray | R17: =DUCCEM_full_SPM!K17 -> 46 | S17: 0.62 | T17: 1.36 | U17: -29.63
A18: 11 | B18: 45090 | C18: 0.5625 | F18: from shoreline_ by hand | G18: up river wind_ waves moving up river_ sediment being moved by waves; a rainy morning but no more during sampling | H18: Lance Gray | I18: 13.62 | J18: 243 | K18: 228.32 | N18: -19.89 | O18: -158.8 | P18: 0.3 | R18: =DUCCEM_full_SPM!K18 -> 52.5 | S18: 0.65 | T18: 1.23 | U18: -30.97 | V18: =DUCCEM_full_CDOM!BM18:BM132 -> 61.45339 | W18: 3.07644 | X18: =DUCCEM_full_CDOM!WN18 -> 0.01609 | Y18: =DUCCEM_full_CDOM!WO18 -> 0.01732 | Z18: =DUCCEM_full_CDOM!WP18 -> 0.929 | AA18: =(V18/2.303)/AB18 -> 3.3522688 | AB18: 7.96 | AC18: 0.31 | AD18: 21 | AE18: 49 | AF18: 29.1 | AG18: 27 | AH18: 1.02 | AI18: 8.51 | AJ18: 23 | AK18: 8.35 | AL18: < 0.10 | AM18: 1.54 | AN18: 170 | AO18: < 25 | AP18: < 20 | AQ18: < 20 | AR18: < 20 | AS18: < 20 | AT18: < 20 | AU18: < 20 | AV18: 0.08 | AW18: 5.34 | AX18: 35.2 | AY18: < 0.05 | AZ18: 0.16 | BA18: < 0.10
A19: 12 | B19: 45097 | C19: 0.39930556 | F19: from shoreline | G19: murky water; water has dropped; breezy_ some waves | H19: Lance Gray_ Erika Hille | I19: 14.95 | J19: 258 | K19: 240.64 | N19: -19.76 | O19: -158.2 | P19: 0.1 | R19: =DUCCEM_full_SPM!K19 -> 163.5 | S19: 1.62 | T19: 0.99 | U19: -28.12 | V19: =DUCCEM_full_CDOM!BM19:BM133 -> 72.63395 | W19: 3.600694 | X19: =DUCCEM_full_CDOM!WN19 -> 0.01595 | Y19: =DUCCEM_full_CDOM!WO19 -> 0.01733 | Z19: =DUCCEM_full_CDOM!WP19 -> 0.9204 | AA19: =(V19/2.303)/AB19 -> 3.373138 | AB19: 9.35 | AC19: 0.36 | AD19: 28 | AE19: 50 | AF19: 30.3 | AG19: 35 | AH19: 0.98 | AI19: 8.48 | AJ19: < 20 | AK19: 7.11 | AL19: < 0.10 | AM19: 1.46 | AN19: 179 | AO19: < 25 | AP19: < 20 | AQ19: < 20 | AR19: < 20 | AS19: < 20 | AT19: < 20 | AU19: < 20 | AV19: 0.08 | AW19: 6.11 | AX19: 34.2 | AY19: < 0.05 | AZ19: 0.11 | BA19: < 0.10
A20: 13 | B20: 45104 | C20: 0.40972222 | D20: 68.3381 | E20: -133.7058 | F20: from dock ~10 m from shore | G20: murky water_ breeze from downriver_ small waves up river | H20: Lance Gray | I20: 16.78 | J20: 263 | K20: 242.04 | N20: -19.54 | O20: -156.2 | P20: 0.1 | R20: =AVERAGE(R21:R23) -> 42.833333 | V20: =DUCCEM_full_CDOM!BM20:BM134 -> 49.54743 | W20: 2.325201 | X20: =DUCCEM_full_CDOM!WN20 -> 0.01688 | Y20: =DUCCEM_full_CDOM!WO20 -> 0.01745 | Z20: =DUCCEM_full_CDOM!WP20 -> 0.9673 | AA20: =(V20/2.303)/AB20 -> 3.1499705 | AB20: 6.83 | AC20: 0.31 | AD20: < 20 | AE20: 47 | AF20: 29 | AG20: < 20 | AH20: 0.84 | AI20: 9.13 | AJ20: < 20 | AK20: 7.16 | AL20: < 0.10 | AM20: 1.55 | AN20: 187 | AO20: < 25 | AP20: < 20 | AQ20: < 20 | AR20: < 20 | AS20: < 20 | AT20: < 20 | AU20: < 20 | AV20: 0.08 | AW20: 6.21 | AX20: 37.8 | AY20: < 0.05 | AZ20: 0.13 | BA20: < 0.10
A21: Transect bottle #1 | B21: 45104 | F21: by hand from boat; furthest from dock side | R21: =DUCCEM_full_SPM!K21 -> 41 | S21: 0.5 | T21: 1.22 | U21: -31.56
A22: Transect bottle #2 | B22: 45104 | F22: by hand from boat; middle river | R22: =DUCCEM_full_SPM!K22 -> 42 | S22: 0.53 | T22: 1.26 | U22: -29.18
A23: Transect bottle #3 | B23: 45104 | F23: by hand from boat; near dock side | R23: =DUCCEM_full_SPM!K23 -> 45.5 | S23: 0.58 | T23: 1.28 | U23: -29.6
A24: blank 3 | B24: 45106 | H24: Lance Gray
A25: 14 | B25: 45111 | C25: 0.42291667 | D25: 68.3381 | E25: -133.7058 | F25: from dock off of upriver side | G25: no wind_ steady flowing river_ murky_ a few minnows near dock | H25: Lance Gray | I25: 20.09 | J25: 287 | K25: 262.47 | N25: -19.25 | O25: -154.5 | P25: -0.6 | R25: =DUCCEM_full_SPM!K25 -> 25.5 | S25: 0.56 | T25: 2.21 | U25: -30.4 | V25: =DUCCEM_full_CDOM!BM25:BM139 -> 36.14126 | W25: 1.387465 | X25: =DUCCEM_full_CDOM!WN25 -> 0.01855 | Y25: =DUCCEM_full_CDOM!WO25 -> 0.01813 | Z25: =DUCCEM_full_CDOM!WP25 -> 1.0232 | AA25: =(V25/2.303)/AB25 -> 2.977822 | AB25: 5.27 | AC25: 0.22 | AD25: < 20 | AE25: 50 | AF25: 30.5 | AG25: < 20 | AH25: 0.86 | AI25: 9.59 | AJ25: < 20 | AK25: 7.89 | AL25: < 0.10 | AM25: 1.47 | AN25: 198 | AO25: < 25 | AP25: < 20 | AQ25: < 20 | AR25: < 20 | AS25: < 20 | AT25: < 20 | AU25: < 20 | AV25: 0.09 | AW25: 7.39 | AX25: 41.1 | AY25: < 0.05 | AZ25: < 0.10 | BA25: < 0.10
A26: 15 | B26: 45118 | C26: 0.56597222 | D26: 68.3381 | E26: -133.7058 | F26: from dock_ up river side | G26: slight up river breeze; murky water; some bits of debris floating | H26: Lance Gray | I26: 21.87 | J26: 305 | K26: 282.2 | N26: -19.18 | O26: -153.4 | P26: 0 | R26: =DUCCEM_full_SPM!K26 -> 40.5 | S26: 0.72 | T26: 1.77 | U26: -29.07 | V26: =DUCCEM_full_CDOM!BM26:BM140 -> 28.26403 | W26: 1.103644 | X26: =DUCCEM_full_CDOM!WN26 -> 0.019 | Y26: =DUCCEM_full_CDOM!WO26 -> 0.01788 | Z26: =DUCCEM_full_CDOM!WP26 -> 1.0626 | AA26: =(V26/2.303)/AB26 -> 2.8474944 | AB26: 4.31 | AC26: 0.24 | AD26: 20 | AE26: 55 | AF26: 32.9 | AG26: < 20 | AH26: 0.85 | AI26: 10.4 | AJ26: < 20 | AK26: 8.11 | AL26: < 0.10 | AM26: 1.64 | AN26: 224 | AO26: < 25 | AP26: < 20 | AQ26: < 20 | AR26: < 20 | AS26: < 20 | AT26: < 20 | AU26: < 20 | AV26: 0.09 | AW26: 9.77 | AX26: 47.1 | AY26: < 0.05 | AZ26: 0.14 | BA26: < 0.10 | BB26: 1.532 | BC26: 0.051 | BD26: 0.1 | BE26: 55.491 | BF26: 0.022
A27: 16 | B27: 45125 | C27: 0.45486111 | D27: 68.3381 | E27: -133.7058 | F27: from dock | G27: light breeze blowing up river; small waves moving up river; murky water | H27: Lance Gray | I27: 20.95 | J27: 279 | K27: 257.46 | N27: -19.06 | O27: -155 | P27: -2.5 | R27: =DUCCEM_full_SPM!K27 -> 30.5 | S27: 0.47 | T27: 1.55 | U27: -30.44 | V27: =DUCCEM_full_CDOM!BM27:BM141 -> 40.43151 | W27: 1.468531 | X27: =DUCCEM_full_CDOM!WN27 -> 0.019 | Y27: =DUCCEM_full_CDOM!WO27 -> 0.01839 | Z27: =DUCCEM_full_CDOM!WP27 -> 1.0332 | AA27: =(V27/2.303)/AB27 -> 2.89226 | AB27: 6.07 | AC27: 0.28 | AD27: < 20 | AE27: 51 | AF27: 30.1 | AG27: < 20 | AH27: 0.87 | AI27: 9.84 | AJ27: < 20 | AK27: 8.04 | AL27: < 0.10 | AM27: 1.23 | AN27: 205 | AO27: < 25 | AP27: < 20 | AQ27: < 20 | AR27: < 20 | AS27: < 20 | AT27: < 20 | AU27: < 20 | AV27: 0.09 | AW27: 7.67 | AX27: 39 | AY27: < 0.05 | AZ27: < 0.10 | BA27: < 0.10 | BB27: 1.663 | BC27: 0.046 | BD27: 0.083 | BE27: 41.68 | BF27: 0.043
A28: 17 | B28: 45132 | C28: 0.40972222 | D28: 68.3381 | E28: -133.7058 | F28: from dock | G28: very light down river breeze (wind from up river to down river); foam/film settled near dock (photo in WhatsApp); low water | H28: Lance Gray | I28: 21.76 | J28: 283 | K28: 258.77 | N28: -18.97 | O28: -154.3 | P28: -2.6 | R28: =AVERAGE(R29:R31) -> 19.5 | V28: =DUCCEM_full_CDOM!BM28:BM142 -> 36.02477 | W28: 1.247719 | X28: =DUCCEM_full_CDOM!WN28 -> 0.0197 | Y28: =DUCCEM_full_CDOM!WO28 -> 0.01843 | Z28: =DUCCEM_full_CDOM!WP28 -> 1.0689 | AA28: =(V28/2.303)/AB28 -> 2.8389365 | AB28: 5.51 | AC28: 0.31 | AD28: < 20 | AE28: 50 | AF28: 29.7 | AG28: < 20 | AH28: 0.85 | AI28: 10.1 | AJ28: < 20 | AK28: 8.33 | AL28: < 0.10 | AM28: 1.26 | AN28: 203 | AO28: < 25 | AP28: < 20 | AQ28: < 20 | AR28: < 20 | AS28: < 20 | AT28: < 20 | AU28: < 20 | AV28: 0.08 | AW28: 8.13 | AX28: 40.9 | AY28: < 0.05 | AZ28: < 0.10 | BA28: < 0.10 | BB28: 0.965 | BC28: 0.046 | BD28: 0.085 | BE28: 42.786 | BF28: 0.012
A29: Transect bottle #1 | B29: 45132 | F29: by hand from boat; closest to dock | R29: =DUCCEM_full_SPM!K29 -> 17.5 | S29: 0.3 | T29: 1.74 | U29: -30.82
A30: Transect bottle #2 | B30: 45132 | F30: by hand from boat; mid river | R30: =DUCCEM_full_SPM!K30 -> 21 | S30: 0.3 | T30: 1.44 | U30: -31.21
A31: Transect bottle #3 | B31: 45132 | F31: by hand from boat; furthest from dock | R31: =DUCCEM_full_SPM!K31 -> 20 | S31: 0.3 | T31: 1.5 | U31: -30.46
A32: blank 4 | B32: 45132
A33: 18 | B33: 45139 | C33: 0.40972222 | D33: 68.3381 | E33: -133.7058 | F33: from dock | G33: calm_ fog/smoke_ light sheen on water_ low water | H33: Lance Gray_ Paul Overduin | I33: 22.25 | J33: 305 | K33: 260.47 | N33: -18.92 | O33: -152.7 | P33: -1.3 | R33: =DUCCEM_full_SPM!K33 -> 14 | S33: 0.37 | T33: 2.66 | U33: -31.15 | V33: =DUCCEM_full_CDOM!BM33:BM147 -> 25.74146 | W33: 0.92401 | X33: =DUCCEM_full_CDOM!WN33 -> 0.02016 | Y33: =DUCCEM_full_CDOM!WO33 -> 0.01806 | Z33: =DUCCEM_full_CDOM!WP33 -> 1.1163 | AA33: =(V33/2.303)/AB33 -> 2.6486635 | AB33: 4.22 | AC33: 0.23 | AD33: 20 | AE33: 43 | AF33: 28.9 | AG33: < 20 | AH33: 0.87 | AI33: 10.9 | AJ33: < 20 | AK33: 8.33 | AL33: < 0.10 | AM33: 1.46 | AN33: 209 | AO33: < 25 | AP33: < 20 | AQ33: < 20 | AR33: < 20 | AS33: < 20 | AT33: < 20 | AU33: < 20 | AV33: 0.09 | AW33: 8.1 | AX33: 45.6 | AY33: < 0.05 | AZ33: < 0.10 | BA33: < 0.10
A34: Discharge 1.1 | B34: 45140 | C34: 0.68888889 | M34: 92.723 | R34: =DUCCEM_full_SPM!K34 -> 0
A35: Discharge 1.2 | B35: 45140 | C35: 0.69722222 | M35: 92.344 | R35: =DUCCEM_full_SPM!K35 -> 0
A36: 19 | B36: 45146 | C36: 0.4375 | D36: 68.3381 | E36: -133.7058 | F36: from dock | G36: no wind_ very smokey_ thin sediment layer on water (ash?)_ low water | H36: Lance Gray | I36: 19.97 | J36: 319 | K36: 281.5 | N36: -18.88 | O36: -151.8 | P36: -0.7 | R36: =DUCCEM_full_SPM!K36 -> 16.5 | S36: 0.46 | T36: 2.79 | U36: -30.96 | V36: =DUCCEM_full_CDOM!BM36:BM150 -> 20.95624 | W36: 0.84253 | X36: =DUCCEM_full_CDOM!WN36 -> 0.02001 | Y36: =DUCCEM_full_CDOM!WO36 -> 0.01737 | Z36: =DUCCEM_full_CDOM!WP36 -> 1.152 | AA36: =(V36/2.303)/AB36 -> 2.2579503 | AB36: 4.03 | AC36: 0.35 | AD36: 20 | AE36: 48 | AF36: 32.2 | AG36: < 20 | AH36: 0.89 | AI36: 11.3 | AJ36: < 20 | AK36: 8.93 | AL36: < 0.10 | AM36: 1.67 | AN36: 234 | AO36: < 25 | AP36: < 20 | AQ36: < 20 | AR36: < 20 | AS36: < 20 | AT36: < 20 | AU36: < 20 | AV36: 0.09 | AW36: 8.58 | AX36: 48.9 | AY36: < 0.05 | AZ36: < 0.10 | BA36: < 0.10 | BB36: 0.523 | BC36: 0.035 | BD36: 0.1 | BE36: 55.89 | BF36: 0.112
A37: Discharge 2.1 | B37: 45149 | C37: 0.63472222 | M37: 96.734 | R37: =DUCCEM_full_SPM!K37 -> 0
A38: Discharge 2.2 | B38: 45149 | C38: 0.6375 | M38: 93.622 | R38: =DUCCEM_full_SPM!K38 -> 0
A39: Discharge 2.3 | B39: 45149 | C39: 0.65416667 | M39: 96.657 | R39: =DUCCEM_full_SPM!K39 -> 0
A40: Discharge 2.4 | B40: 45149 | C40: 0.65833333 | M40: 101.133 | R40: =DUCCEM_full_SPM!K40 -> 0
...

Sheet otherSites_liveResults
A1: ID | B1: Date | C1: Time (local) | D1: Lat (DecDeg) | E1: Lon (DecDeg) | F1: Temp_degC (Â°C) | G1: Cond_ÂµScm (ÂµS/cm) | H1: Discharge (m³/s) | I1: mean d18O | J1: mean dD | K1: mean d xs | L1: comments on sampling location | M1: comments on sampling situation | N1: sampled by | O1: GF-F_FilterID | P1: initialFilter-weight_g | Q1: FilteredVolume_ml | R1: SPM concentration (mg/L) | S1: comment on filtering process | T1: POC (mg/L) | U1: POC (%) | V1: d13C (‰) | W1: aCDOM(254) | X1: Al (µg/L) | Y1: Ba (µg/L) | Z1: Ca (mg/L) | AA1: Fe (µg/L) | AB1: K (mg/L) | AC1: Mg (mg/L) | AD1: Mn (µg/L) | AE1: Na (mg/L) | AF1: P (mg/L) | AG1: Si (mg/L) | AH1: Sr (µg/L) | AI1: Pb (µg/L) | AJ1: Cr (µg/L) | AK1: V (µg/L) | AL1: Co (µg/L) | AM1: Ni (µg/L) | AN1: Cu (µg/L) | AO1: Zn (µg/L) | AP1: Laborroboter Seal Analytical (µS/cm) | AQ1: Felddaten TRef. ? (µS/cm) | AR1: NO3 [µmol/l] | AS1: NO2 [µmol/l] | AT1: PO4 [µmol/l] | AU1: Si [µmol/l] | AV1: NH4* [µmol]
A2: MHPaul1 | B2: 45146 | D2: 69.0602 | E2: 135.05836 | I2: -19.1 | J2: -152.7 | K2: 0.1 | N2: Paul Overduin | O2: 33 | P2: 0.127 | Q2: 242 | R2: 25.206612 | T2: 0.34 | U2: 1.35 | V2: -30.9 | W2: 0.418448 | X2: 21 | Y2: 50 | Z2: 34.1 | AA2: < 20 | AB2: 0.87 | AC2: 11.8 | AD2: < 20 | AE2: 8.38 | AF2: < 0,10 | AG2: 1.74 | AH2: 234 | AI2: < 25 | AJ2: < 20 | AK2: < 20 | AL2: < 20 | AM2: < 20 | AN2: < 20 | AO2: < 20 | AP2: 296.62 | AQ2: /
A3: MHPaul2 | B3: 45146 | D3: 68.63536 | E3: 134.08055 | I3: -18.95 | J3: -152.4 | K3: -0.8 | N3: Paul Overduin | O3: 32 | P3: 0.1285 | Q3: 315.4 | R3: 12.36525 | T3: 0.38 | U3: 3.09 | V3: -31.68 | W3: 0.488119 | X3: < 20 | Y3: 110 | Z3: 34.8 | AA3: < 20 | AB3: 0.88 | AC3: 11.6 | AD3: < 20 | AE3: 8.71 | AF3: < 0,10 | AG3: 1.61 | AH3: 241 | AI3: < 25 | AJ3: < 20 | AK3: < 20 | AL3: < 20 | AM3: < 20 | AN3: < 20 | AO3: < 20 | AP3: 296.62 | AQ3: / | AR3: 1.429 | AS3: 0.058 | AT3: 0.1 | AU3: 52.107 | AV3: 0.019
A4: MHPaul3-A | B4: 45146 | D4: 68.6237 | E4: 134.18918 | I4: -19.06 | J4: -153.1 | K4: -0.6 | N4: Paul Overduin | O4: 99 | P4: 0.1308 | Q4: 240 | R4: 57.5 | T4: 0.81 | U4: 1.41 | V4: -29.9 | W4: 0.46281 | X4: < 20 | Y4: 71 | Z4: 34.3 | AA4: < 20 | AB4: 0.85 | AC4: 11.6 | AD4: < 20 | AE4: 8.32 | AF4: < 0,10 | AG4: 1.72 | AH4: 237 | AI4: < 25 | AJ4: < 20 | AK4: < 20 | AL4: < 20 | AM4: < 20 | AN4: < 20 | AO4: < 20 | AP4: 296.22 | AQ4: /
A5: MHKalinek-A | B5: 45147 | D5: 67.99232 | E5: 134.1269 | I5: -18.92 | J5: -152.2 | K5: -0.9 | N5: Paul Overduin | O5: 96 | P5: 0.1303 | Q5: 211 | R5: 49.763033 | T5: 0.44 | U5: 0.89 | V5: -30.91 | W5: 0.438243 | X5: 23 | Y5: 49 | Z5: 33.2 | AA5: < 20 | AB5: 0.86 | AC5: 11.6 | AD5: < 20 | AE5: 8.27 | AF5: < 0,10 | AG5: 1.77 | AH5: 239 | AI5: < 25 | AJ5: < 20 | AK5: < 20 | AL5: < 20 | AM5: < 20 | AN5: < 20 | AO5: < 20 | AP5: 292.51 | AQ5: /
A6: MHPaul4 | B6: 45148 | D6: 68.32398 | E6: 134.22436 | I6: -19.13 | J6: -152.8 | K6: 0.2 | N6: Paul Overduin | O6: 109 | P6: 0.128 | Q6: 223.1 | R6: 77.095473 | T6: 0.93 | U6: 1.21 | V6: -29.49 | W6: 0.421456 | X6: 21 | Y6: 58 | Z6: 38.1 | AA6: < 20 | AB6: 0.86 | AC6: 11.8 | AD6: < 20 | AE6: 8.01 | AF6: < 0,10 | AG6: 1.75 | AH6: 262 | AI6: < 25 | AJ6: < 20 | AK6: < 20 | AL6: < 20 | AM6: < 20 | AN6: < 20 | AO6: < 20 | AP6: 317.35 | AQ6: /
A7: MHPaul5 | B7: 45149 | D7: 68.35192 | E7: 133.72331 | I7: -18.72 | J7: -150.1 | K7: -0.3 | N7: Paul Overduin | O7: 100 | P7: 0.1285 | Q7: 200.7 | R7: 46.836074 | T7: 1.3 | U7: 2.77 | V7: -29.57 | W7: 0.543335 | X7: < 20 | Y7: 135 | Z7: 37.3 | AA7: < 20 | AB7: 0.97 | AC7: 11.9 | AD7: 107 | AE7: 8.63 | AF7: < 0,10 | AG7: 1.43 | AH7: 243 | AI7: < 25 | AJ7: < 20 | AK7: < 20 | AL7: < 20 | AM7: < 20 | AN7: < 20 | AO7: < 20 | AP7: 310.34 | AQ7: / | AR7: 0.5 | AS7: 0.055 | AT7: 0.066 | AU7: 42.869 | AV7: 0.179
A8: sample peel river | B8: 20.08.2023 | D8: 67.338718 | E8: -134.87376 | I8: -21.97 | J8: -171.8 | K8: 4 | O8: 36 | P8: 0.1299 | Q8: 255 | R8: 64.706 | T8: 1.25 | U8: =100/R8*T8 -> 1.9318147 | V8: -28.09 | W8: 0.223063 | X8: < 20 | Y8: 47 | Z8: 43.8 | AA8: < 20 | AB8: 0.69 | AC8: 23 | AD8: < 20 | AE8: 6.59 | AF8: < 0,10 | AG8: 1.37 | AH8: 167 | AI8: < 25 | AJ8: < 20 | AK8: < 20 | AL8: < 20 | AM8: < 20 | AN8: < 20 | AO8: < 20 | AP8: 420.39
A9: sample peel river | B9: 20.08.2023 | D9: 67.338718 | E9: -134.87376 | O9: 37 | P9: 0.1229 | Q9: 288 | R9: 58.333 | T9: 0.69 | U9: =100/R9*T9 -> 1.1828639 | V9: -27.64
A10: SPOT1 | B10: 19.08.2023 | D10: 65.715158 | E10: -137.99277 | I10: -21.91 | J10: -171.3 | K10: 4 | O10: 44 | P10: 0.1275 | Q10: 507 | R10: 4.734 | T10: 0.26 | U10: =100/R10*T10 -> 5.4921842 | V10: -30.13 | W10: 0.302289 | X10: 40 | Y10: 50 | Z10: 57.3 | AA10: < 20 | AB10: 0.69 | AC10: 31 | AD10: < 20 | AE10: 21.1 | AF10: < 0,10 | AG10: 0.64 | AH10: 303 | AI10: < 25 | AJ10: < 20 | AK10: < 20 | AL10: < 20 | AM10: 21 | AN10: < 20 | AO10: < 20 | AP10: 606.06
A11: SPOT2 | B11: 19.08.2023 | D11: 64.948668 | E11: -138.27699 | I11: -19.84 | J11: -152.6 | K11: 6.1 | O11: 42 | P11: 0.1231 | Q11: 479 | R11: 0.418 | T11: 0.01 | U11: =100/R11*T11 -> 2.3923445 | V11: -33.93 | W11: 1.507141 | X11: < 20 | Y11: 121 | Z11: 23.5 | AA11: < 20 | AB11: 0.21 | AC11: 14.4 | AD11: < 20 | AE11: 0.92 | AF11: < 0,10 | AG11: 2.16 | AH11: 49 | AI11: < 25 | AJ11: < 20 | AK11: < 20 | AL11: < 20 | AM11: < 20 | AN11: < 20 | AO11: < 20 | AP11: 220.21
A12: SPOT3 | B12: 19.08.2023 | D12: 64.777413 | E12: -138.36349 | I12: -22.8 | J12: -178 | K12: 4.3 | O12: 40 | P12: 0.1235 | Q12: 495 | R12: -0.404 | T12: 0.02 | U12: =100/R12*T12 -> -4.950495 | V12: -34.68 | W12: 0.050924 | X12: < 20 | Y12: 36 | Z12: 33.5 | AA12: < 20 | AB12: 0.62 | AC12: 11.9 | AD12: < 20 | AE12: 4.18 | AF12: < 0,10 | AG12: 2.69 | AH12: 192 | AI12: < 25 | AJ12: < 20 | AK12: < 20 | AL12: < 20 | AM12: < 20 | AN12: < 20 | AO12: < 20 | AP12: 291.61
A13: SPOT4 | B13: 19.08.2023 | D13: 64.835491 | E13: -138.36178 | I13: -21.98 | J13: -172.1 | K13: 3.8 | O13: 43 | P13: 0.1235 | Q13: 467 | R13: 0.428 | S13: volume could be 467 or 407mL not clear writing | T13: 0.13 | U13: =100/R13*T13 -> 30.373832 | V13: -32.25 | W13: 0.179235 | X13: < 20 | Y13: 31 | Z13: 34.7 | AA13: < 20 | AB13: 0.59 | AC13: 18.3 | AD13: < 20 | AE13: 2.94 | AF13: < 0,10 | AG13: 2.16 | AH13: 161 | AI13: < 25 | AJ13: < 20 | AK13: < 20 | AL13: < 20 | AM13: < 20 | AN13: < 20 | AO13: < 20 | AP13: 344.19
A14: SPOT5 | B14: 19.08.2023 | D14: 64.605771 | E14: -138.34077 | I14: -21.97 | J14: -171.5 | K14: 4.2 | O14: 39 | P14: 0.1217 | Q14: 484 | R14: 5.372 | T14: 0.13 | U14: =100/R14*T14 -> 2.4199553 | V14: -32.91 | W14: 0.11455 | X14: 47 | Y14: 26 | Z14: 58.4 | AA14: < 20 | AB14: 0.59 | AC14: 39 | AD14: 175 | AE14: 4.41 | AF14: < 0,10 | AG14: 1.42 | AH14: 452 | AI14: < 25 | AJ14: < 20 | AK14: < 20 | AL14: < 20 | AM14: 22 | AN14: < 20 | AO14: < 20 | AP14: 587.13
A15: SPOT7 | B15: 20.08.2023 | D15: 67.105681 | E15: -136.09141 | I15: -21.29 | J15: -167.1 | K15: 3.2 | O15: 41 | P15: 0.1281 | Q15: 466 | R15: 2.575 | T15: 0.08 | U15: =100/R15*T15 -> 3.1067961 | V15: -31.12 | W15: 0.142301 | X15: < 20 | Y15: < 20 | Z15: 110 | AA15: < 20 | AB15: 1.04 | AC15: 111 | AD15: 608 | AE15: 22.3 | AF15: < 0,10 | AG15: 2.3 | AH15: 833 | AI15: < 25 | AJ15: < 20 | AK15: < 20 | AL15: < 20 | AM15: 51 | AN15: < 20 | AO15: 32 | AP15: 1331.88
A16: sample point 8 | B16: 20.08.2023 | D16: 67.177106 | E16: -135.72466 | I16: -21.72 | J16: -171.9 | K16: 1.8 | W16: 0.163463 | X16: 27 | Y16: 34 | Z16: 99 | AA16: < 20 | AB16: 6.3 | AC16: 37.1 | AD16: 813 | AE16: 29.9 | AF16: < 0,10 | AG16: 0.74 | AH16: 208 | AI16: < 25 | AJ16: < 20 | AK16: < 20 | AL16: < 20 | AM16: < 20 | AN16: < 20 | AO16: < 20 | AP16: 910.19
A17: SPOT10 | B17: 20.08.2023 | D17: 67.178676 | E17: -135.82373 | I17: -20.16 | J17: -155.3 | K17: 5.9 | O17: 38 | P17: 0.1275 | Q17: 604 | R17: 0.166 | T17: 0.11 | U17: =100/R17*T17 -> 66.26506 | V17: -30.97 | W17: 0.359154 | X17: < 20 | Y17: 87 | Z17: 6.19 | AA17: < 20 | AB17: 0.21 | AC17: 2.3 | AD17: 29 | AE17: 0.54 | AF17: < 0,10 | AG17: 0.27 | AH17: 22 | AI17: < 25 | AJ17: < 20 | AK17: < 20 | AL17: < 20 | AM17: < 20 | AN17: < 20 | AO17: 25 | AP17: 63.86
A18: SPOT1 | B18: 45466 | C18: 0.65625 | D18: 65.715158 | E18: -137.99277 | I18: -22.1 | J18: -173.9 | K18: 2.9 | O18: 01 (FLOCHAR set) | P18: 1288 | Q18: 700 | R18: 12.28571 | X18: 58 | Y18: 55 | Z18: 64.9 | AA18: < 20 | AB18: 0.69 | AC18: 32.1 | AD18: 24 | AE18: 21.6 | AF18: < 0.10 | AG18: 0.27 | AH18: 317 | AI18: < 25 | AJ18: < 20 | AK18: < 20 | AL18: < 20 | AM18: < 20 | AN18: < 20 | AO18: < 20 | AP18: 672.15
A19: SPOT2 | B19: 45466 | C19: 0.58333333 | D19: 64.948668 | E19: -138.27699 | I19: -21.83 | J19: -172 | K19: 2.7 | O19: 02 (FLOCHAR set) | P19: 0.1286 | Q19: 675 | R19: 0.888889 | X19: < 20 | Y19: 165 | Z19: 29 | AA19: < 20 | AB19: 0.39 | AC19: 18.2 | AD19: < 20 | AE19: 1.32 | AF19: < 0.10 | AG19: 1.44 | AH19: 56 | AI19: < 25 | AJ19: < 20 | AK19: < 20 | AL19: < 20 | AM19: < 20 | AN19: < 20 | AO19: < 20 | AP19: 286.41
A20: SPOT3 | B20: 45465 | C20: 0.70833333 | D20: 64.777413 | E20: -138.36349 | I20: -22.38 | J20: -174.6 | K20: 4.5 | O20: 03 (FLOCHAR set) | P20: 0.1302 | Q20: 500 | R20: 1.2 | X20: < 20 | Y20: 72 | Z20: 50.8 | AA20: < 20 | AB20: 0.66 | AC20: 13.3 | AD20: < 20 | AE20: 4.48 | AF20: < 0.10 | AG20: 2.47 | AH20: 249 | AI20: < 25 | AJ20: < 20 | AK20: < 20 | AL20: < 20 | AM20: < 20 | AN20: < 20 | AO20: < 20 | AP20: 376.13
A21: SPOT4 | B21: 45465 | C21: 0.69444444 | D21: 64.835491 | E21: -138.36178 | I21: -21.94 | J21: -171.2 | K21: 4.3 | O21: 04 (FLOCHAR set) | P21: 0.129 | Q21: 550 | R21: 8.181818 | X21: 22 | Y21: 34 | Z21: 39.4 | AA21: < 20 | AB21: 0.59 | AC21: 20.9 | AD21: < 20 | AE21: 3.01 | AF21: < 0.10 | AG21: 1.33 | AH21: 198 | AI21: < 25 | AJ21: < 20 | AK21: < 20 | AL21: < 20 | AM21: < 20 | AN21: < 20 | AO21: < 20 | AP21: 385.25
A22: SPOT5 | B22: 45465 | C22: 0.80555556 | D22: 64.605771 | E22: -138.34077 | I22: -21.97 | J22: -170.4 | K22: 5.4 | O22: 05 (FLOCHAR set) | P22: 0.1297 | Q22: 570 | R22: 15.26316 | X22: 88 | Y22: 24 | Z22: 57.4 | AA22: < 20 | AB22: 0.59 | AC22: 39.7 | AD22: 228 | AE22: 3.45 | AF22: < 0.10 | AG22: 0.37 | AH22: 389 | AI22: < 25 | AJ22: < 20 | AK22: < 20 | AL22: < 20 | AM22: 41 | AN22: < 20 | AO22: 73 | AP22: 613.27
A23: SPOT6 | B23: 45467 | C23: 0.34375 | D23: 67.079407 | E23: -136.16746 | I23: -20.87 | J23: -159.8 | K23: 7.2 | O23: 06 (FLOCHAR set) | P23: 0.1304 | Q23: 550 | R23: 0.909091 | X23: 39 | Y23: 46 | Z23: 17.3 | AA23: < 20 | AB23: 0.41 | AC23: 10.7 | AD23: 23 | AE23: 1.6 | AF23: < 0.10 | AG23: < 0.10 | AH23: 57 | AI23: < 25 | AJ23: < 20 | AK23: < 20 | AL23: < 20 | AM23: 21 | AN23: < 20 | AO23: 52 | AP23: 214
A24: SPOT7 | B24: 45467 | C24: 0.34722222 | D24: 67.105681 | E24: -136.09141 | I24: -22.17 | J24: -170.6 | K24: 6.8 | O24: 08 (FLOCHAR set) | P24: 0.129 | Q24: 653.8 | R24: 1.223616 | X24: < 20 | Y24: < 20 | Z24: 53 | AA24: < 20 | AB24: 0.71 | AC24: 52.8 | AD24: 290 | AE24: 13.2 | AF24: < 0.10 | AG24: 1.55 | AH24: 447 | AI24: < 25 | AJ24: < 20 | AK24: < 20 | AL24: < 20 | AM24: 29 | AN24: < 20 | AO24: 21 | AP24: 793.12
A25: sample 8 | B25: 45467 | C25: 0.6875 | D25: 67.177106 | E25: -135.72466 | I25: -23.02 | J25: -179.8 | K25: 4.3 | O25: 07 (FLOCHAR set) | P25: 0.1303 | Q25: 80 | R25: 2987.5 | S25: after drying filter got partly stuck to petri dish, some residues left on petri dish | X25: 45 | Y25: 45 | Z25: 23.4 | AA25: 30 | AB25: 2.49 | AC25: 7.68 | AD25: 153 | AE25: 6.95 | AF25: < 0.10 | AG25: 0.29 | AH25: 53 | AI25: < 25 | AJ25: < 20 | AK25: < 20 | AL25: < 20 | AM25: < 20 | AN25: < 20 | AO25: < 20 | AP25: 229.42
A26: sample 9 | B26: 45467 | C26: 0.66666667 | D26: 67.177111 | E26: -135.72767 | I26: -23.55 | J26: -182.4 | K26: 6 | O26: 09 (FLOCHAR set) | P26: 0.1299 | Q26: 699.1 | R26: 2.288657 | X26: < 20 | Y26: 22 | Z26: 8.78 | AA26: < 20 | AB26: 0.43 | AC26: 3.06 | AD26: < 20 | AE26: 0.83 | AF26: < 0.10 | AG26: 1.01 | AH26: 67 | AI26: < 25 | AJ26: < 20 | AK26: < 20 | AL26: < 20 | AM26: < 20 | AN26: < 20 | AO26: < 20 | AP26: 82.75
A27: SPOT10 | B27: 45467 | C27: 0.375 | D27: 67.178676 | E27: -135.82373 | I27: -21.97 | J27: -168.6 | K27: 7.2 | O27: 10 (FLOCHAR set) | P27: 0.1305 | Q27: 665.9 | R27: 0.300345 | X27: < 20 | Y27: 56 | Z27: 4.49 | AA27: < 20 | AB27: 0.26 | AC27: 1.5 | AD27: < 20 | AE27: 0.33 | AF27: < 0.10 | AG27: 0.14 | AH27: < 20 | AI27: < 25 | AJ27: < 20 | AK27: < 20 | AL27: < 20 | AM27: < 20 | AN27: < 20 | AO27: < 20 | AP27: 48.05
A28: Ferry Crossing FMP | B28: 45467 | C28: 0.70833333 | D28: 67.338832 | E28: -134.87372 | O28: 11 (FLOCHAR set) | P28: 0.1288 | Q28: 586.6 | R28: 64.78009 | X28: < 20 | Y28: 33 | Z28: 34.2 | AA28: < 20 | AB28: 0.56 | AC28: 19.7 | AD28: < 20 | AE28: 5.46 | AF28: < 0.10 | AG28: 1.15 | AH28: 125 | AI28: < 25 | AJ28: < 20 | AK28: < 20 | AL28: < 20 | AM28: < 20 | AN28: < 20 | AO28: < 20 | AP28: 358.61
A29: RSP2 D | B29: 45533 | C29: / | O29: 147 (FLOCHAR set) | P29: 0.1281 | Q29: 1000 | R29: 2.2 | X29: < 20 | Y29: 177 | Z29: 29.7 | AA29: < 20 | AB29: 0.22 | AC29: 15.3 | AD29: < 20 | AE29: 0.87 | AF29: < 0.10 | AG29: 1.83 | AH29: 55 | AI29: < 25 | AJ29: < 20 | AK29: < 20 | AL29: < 20 | AM29: < 20 | AN29: < 20 | AO29: < 20 | AP29: 262.97
A30: RSP3 B | B30: 45533 | C30: / | O30: 143 (FLOCHAR set) | P30: 0.129 | Q30: 1050 | R30: 1.333333 | X30: < 20 | Y30: 55 | Z30: 40.7 | AA30: < 20 | AB30: 0.66 | AC30: 12.8 | AD30: < 20 | AE30: 4.23 | AF30: < 0.10 | AG30: 2.62 | AH30: 216 | AI30: < 25 | AJ30: < 20 | AK30: < 20 | AL30: < 20 | AM30: < 20 | AN30: < 20 | AO30: < 20 | AP30: 332.87
A31: RSP4 C | B31: 45533 | C31: / | O31: 145 (FLOCHAR set) | P31: 0.1297 | Q31: 1100 | R31: 5.363636 | X31: 56 | Y31: 61 | Z31: 57.7 | AA31: < 20 | AB31: 0.67 | AC31: 26.4 | AD31: 77 | AE31: 3.5 | AF31: < 0.10 | AG31: 1.32 | AH31: 253 | AI31: < 25 | AJ31: < 20 | AK31: < 20 | AL31: < 20 | AM31: 25 | AN31: < 20 | AO31: < 20 | AP31: 508.92
A32: RSP5 A | B32: 45533 | C32: / | O32: 149 (FLOCHAR set) | P32: 0.1287 | Q32: 900 | R32: 14 | X32: 172 | Y32: 28 | Z32: 79.2 | AA32: < 20 | AB32: 0.74 | AC32: 53.3 | AD32: 728 | AE32: 5.24 | AF32: < 0.10 | AG32: 0.51 | AH32: 524 | AI32: < 25 | AJ32: < 20 | AK32: < 20 | AL32: < 20 | AM32: 61 | AN32: < 20 | AO32: 38 | AP32: 855.31
A33: RSP1 E | B33: 45534 | C33: / | O33: 150 (FLOCHAR set) | P33: 0.1318 | Q33: 900 | R33: 12 | X33: 71 | Y33: 72 | Z33: 68.5 | AA33: < 20 | AB33: 0.65 | AC33: 33.1 | AD33: 47 | AE33: 25.3 | AF33: < 0.10 | AG33: 0.48 | AH33: 350 | AI33: < 25 | AJ33: < 20 | AK33: < 20 | AL33: < 20 | AM33: 22 | AN33: < 20 | AO33: < 20 | AP33: 704.8
A34: RSP6 | B34: 45534 | C34: / | O34: 146 (FLOCHAR set) | P34: 0.13 | Q34: 1000 | R34: 13.9 | X34: 34 | Y34: 38 | Z34: 13.6 | AA34: 28 | AB34: 0.51 | AC34: 8.59 | AD34: 36 | AE34: 1.45 | AF34: < 0.10 | AG34: < 0.10 | AH34: 43 | AI34: < 25 | AJ34: < 20 | AK34: < 20 | AL34: < 20 | AM34: < 20 | AN34: < 20 | AO34: 38 | AP34: 172.84
A35: RSP8 | B35: 45534 | C35: / | O35: 151 (FLOCHAR set) | P35: 0.13 | Q35: 100 | R35: 353 | X35: 42 | Y35: 63 | Z35: 15.6 | AA35: 177 | AB35: 0.56 | AC35: 7 | AD35: 309 | AE35: 1.82 | AF35: < 0.10 | AG35: 0.35 | AH35: 42 | AI35: < 25 | AJ35: < 20 | AK35: < 20 | AL35: < 20 | AM35: < 20 | AN35: < 20 | AO35: 30 | AP35: 166.64
A36: RSP9 | B36: 45534 | C36: / | O36: 148 (FLOCHAR set) | P36: 0.1302 | Q36: 1000 | R36: 2.8 | X36: < 20 | Y36: 35 | Z36: 14 | AA36: 40 | AB36: 0.43 | AC36: 5.14 | AD36: < 20 | AE36: 1.47 | AF36: < 0.10 | AG36: 1.89 | AH36: 104 | AI36: < 25 | AJ36: < 20 | AK36: < 20 | AL36: < 20 | AM36: < 20 | AN36: < 20 | AO36: < 20 | AP36: 127.88
A37: RSP10 | B37: 45534 | C37: / | O37: 144 (FLOCHAR set) | P37: 0.1308 | Q37: 1100 | R37: 0.909091 | X37: < 20 | Y37: 109 | Z37: 8.93 | AA37: < 20 | AB37: 0.31 | AC37: 3.38 | AD37: 57 | AE37: 0.7 | AF37: < 0.10 | AG37: 0.36 | AH37: 29 | AI37: < 25 | AJ37: < 20 | AK37: < 20 | AL37: < 20 | AM37: < 20 | AN37: < 20 | AO37: 38 | AP37: 94.75
A38: Fort McPherson | B38: 45535 | C38: / | O38: 152 (FLOCHAR set) | P38: 0.1294 | Q38: 80 | R38: 421.25 | X38: < 20 | Y38: 55 | Z38: 53.3 | AA38: < 20 | AB38: 0.68 | AC38: 25.5 | AD38: < 20 | AE38: 8.08 | AF38: < 0.10 | AG38: 1 | AH38: 206 | AI38: < 25 | AJ38: < 20 | AK38: < 20 | AL38: < 20 | AM38: < 20 | AN38: < 20 | AO38: < 20 | AP38: 501.11
A39: GF/F Filterblank#1 | B39: 45543 | C39: 0.77083333 | O39: 153 (FLOCHAR set) | P39: 0.1307 | Q39: 1000 | R39: 0.3
A40: GF/F Filterblank#2 | B40: 45543 | C40: 0.77083333 | O40: 154 (FLOCHAR set) | P40: 0.131 | Q40: 900 | R40: 0.111111
...

Sheet Discharge_Gauge
A1: river | B1: agency | C1: station_code | D1: station_name | E1: date | F1: discharge | G1: flag
A2: Mackenzie | B2: Water Survey of Canada | C2: 10LC014 | D2: Arctic Red River | E2: 26379 | F2: 2290 | G2: A
A3: Mackenzie | B3: NA | C3: NA | D3: NA | E3: 26380 | F3: NA | G3: NA
A4: Mackenzie | B4: NA | C4: NA | D4: NA | E4: 26381 | F4: NA | G4: NA
A5: Mackenzie | B5: NA | C5: NA | D5: NA | E5: 26382 | F5: NA | G5: NA
A6: Mackenzie | B6: NA | C6: NA | D6: NA | E6: 26383 | F6: NA | G6: NA
A7: Mackenzie | B7: NA | C7: NA | D7: NA | E7: 26384 | F7: NA | G7: NA
A8: Mackenzie | B8: NA | C8: NA | D8: NA | E8: 26385 | F8: NA | G8: NA
A9: Mackenzie | B9: NA | C9: NA | D9: NA | E9: 26386 | F9: NA | G9: NA
A10: Mackenzie | B10: NA | C10: NA | D10: NA | E10: 26387 | F10: NA | G10: NA
A11: Mackenzie | B11: NA | C11: NA | D11: NA | E11: 26388 | F11: NA | G11: NA
A12: Mackenzie | B12: NA | C12: NA | D12: NA | E12: 26389 | F12: NA | G12: NA
A13: Mackenzie | B13: NA | C13: NA | D13: NA | E13: 26390 | F13: NA | G13: NA
A14: Mackenzie | B14: NA | C14: NA | D14: NA | E14: 26391 | F14: NA | G14: NA
... A51: Mackenzie | B51: NA | C51: NA | D51: NA | E51: 26428 | F51: NA | G51: NA
A52: Mackenzie | B52: Water Survey of Canada | C52: 10LC014 | D52: Arctic Red River | E52: 26429 | F52: 2970 | G52: A
A53: Mackenzie | B53: NA | C53: NA | D53: NA | E53: 26430 | F53: NA | G53: NA
A54: Mackenzie | B54: NA | C54: NA | D54: NA | E54: 26431 | F54: NA | G54: NA
A55: Mackenzie | B55: NA | C55: NA | D55: NA | E55: 26432 | F55: NA | G55: NA
A56: Mackenzie | B56: NA | C56: NA | D56: NA | E56: 26433 | F56: NA | G56: NA
A57: Mackenzie | B57: NA | C57: NA | D57: NA | E57: 26434 | F57: NA | G57: NA
A58: Mackenzie | B58: NA | C58: NA | D58: NA | E58: 26435 | F58: NA | G58: NA
A59: Mackenzie | B59: NA | C59: NA | D59: NA | E59: 26436 | F59: NA | G59: NA
A60: Mackenzie | B60: NA | C60: NA | D60: NA | E60: 26437 | F60: NA | G60: NA
A61: Mackenzie | B61: NA | C61: NA | D61: NA | E61: 26438 | F61: NA | G61: NA
A62: Mackenzie | B62: NA | C62: NA | D62: NA | E62: 26439 | F62: NA | G62: NA
A63: Mackenzie | B63: NA | C63: NA | D63: NA | E63: 26440 | F63: NA | G63: NA
A64: Mackenzie | B64: NA | C64: NA | D64: NA | E64: 26441 | F64: NA | G64: NA
... A114: Mackenzie | B114: NA | C114: NA | D114: NA | E114: 26491 | F114: NA | G114: NA
A115: Mackenzie | B115: Water Survey of Canada | C115: 10LC014 | D115: Arctic Red River | E115: 26492 | F115: 17600 | G115: A
A116: Mackenzie | B116: Water Survey of Canada | C116: 10LC014 | D116: Arctic Red River | E116: 26493 | F116: 17100 | G116: A
A117: Mackenzie | B117: Water Survey of Canada | C117: 10LC014 | D117: Arctic Red River | E117: 26494 | F117: 16600 | G117: A
A118: Mackenzie | B118: Water Survey of Canada | C118: 10LC014 | D118: Arctic Red River | E118: 26495 | F118: 16100 | G118: A
A119: Mackenzie | B119: Water Survey of Canada | C119: 10LC014 | D119: Arctic Red River | E119: 26496 | F119: 15800 | G119: A
A120: Mackenzie | B120: Water Survey of Canada | C120: 10LC014 | D120: Arctic Red River | E120: 26497 | F120: 15500 | G120: A
A121: Mackenzie | B121: Water Survey of Canada | C121: 10LC014 | D121: Arctic Red River | E121: 26498 | F121: 15300 | G121: A
A122: Mackenzie | B122: Water Survey of Canada | C122: 10LC014 | D122: Arctic Red River | E122: 26499 | F122: 15100 | G122: A
A123: Mackenzie | B123: NA | C123: NA | D123: NA | E123: 26500 | F123: NA | G123: NA
A124: Mackenzie | B124: NA | C124: NA | D124: NA | E124: 26501 | F124: NA | G124: NA
A125: Mackenzie | B125: NA | C125: NA | D125: NA | E125: 26502 | F125: NA | G125: NA
...

Sheet Isoptopes_full
A1: ID | B1: Date | C1: Time | D1: d18O (pro mille) | E1: 1 σ | F1: dD (pro mille) | G1: 1 σ | H1: D - excess (pro mille)
A2: 1 | B2: 45050 | C2: 0.625 | D2: -18.42 | E2: 0.02 | F2: -149.8 | G2: 0.1 | H2: -2.4
A3: TSI | B3: 45051 | C3: 0.5 | D3: -18.35 | F3: -149 | H3: -2.2
A4: blank 1 | B4: 45051
A5: 2 | B5: 45051 | C5: 0.64583333 | D5: -18.38 | E5: 0.02 | F5: -149 | G5: 0.1 | H5: -2
A6: 3 | B6: 45054 | C6: 0.45833333 | D6: -18.43 | E6: 0.02 | F6: -148.5 | G6: 0.1 | H6: -1.1
A7: 4 | B7: 45055 | C7: 0.41666667 | D7: -18.4 | E7: 0.01 | F7: -149.1 | G7: 0.2 | H7: -1.8
A8: 5 | B8: 45056 | C8: 0.41666667 | D8: -18.4 | E8: 0.01 | F8: -149.1 | G8: 0.2 | H8: -1.9
A9: 6 | B9: 45062 | C9: 0.38888889 | D9: -19.25 | E9: 0.01 | F9: -154.8 | G9: 0.2 | H9: -0.8
A10: 7 | B10: 45069 | C10: 0.41666667 | D10: -20.08 | E10: 0.02 | F10: -160.4 | G10: 0.2 | H10: 0.2
A11: blank 2 | B11: 45069
A12: 8 | B12: 45072 | C12: 0.45138889 | D12: -20.59 | E12: 0.01 | F12: -164.2 | G12: 0.1 | H12: 0.6
A13: 9 | B13: 45076 | C13: 0.46527778 | D13: -20.43 | E13: 0.02 | F13: -163.1 | G13: 0.3 | H13: 0.3
A14: 10 | B14: 45083 | C14: 0.56597222 | D14: -20.19 | E14: 0.01 | F14: -160.9 | G14: 0.1 | H14: 0.7
A15: Transect bottle #1 | B15: 45086
A16: Transect bottle #2 | B16: 45086
A17: Transect bottle #3 | B17: 45086
A18: 11 | B18: 45090 | C18: 0.5625 | D18: -19.89 | E18: 0.02 | F18: -158.8 | G18: 0.3 | H18: 0.3
A19: 12 | B19: 45097 | C19: 0.39930556 | D19: -19.76 | E19: 0.01 | F19: -158.2 | G19: 0.2 | H19: 0.1
A20: 13 | B20: 45104 | C20: 0.40972222 | D20: -19.54 | E20: 0.02 | F20: -156.2 | G20: 0.2 | H20: 0.1
A21: Transect bottle #1 | B21: 45104
A22: Transect bottle #2 | B22: 45104
A23: Transect bottle #3 | B23: 45104
A24: blank 3 | B24: 45106
A25: 14 | B25: 45111 | C25: 0.42291667 | D25: -19.25 | E25: 0.02 | F25: -154.5 | G25: 0.2 | H25: -0.6
A26: 15 | B26: 45118 | C26: 0.56597222 | D26: -19.18 | E26: 0.02 | F26: -153.4 | G26: 0.25 | H26: 0
A27: 16 | B27: 45125 | C27: 0.45486111 | D27: -19.06 | E27: 0.015 | F27: -155 | G27: 0.15 | H27: -2.5
A28: 17 | B28: 45132 | C28: 0.40972222 | D28: -18.97 | E28: 0.02 | F28: -154.3 | G28: 0.2 | H28: -2.6
A29: Transect bottle #1 | B29: 45132
A30: Transect bottle #2 | B30: 45132
A31: Transect bottle #3 | B31: 45132
A32: blank 4 | B32: 45132
A33: 18 | B33: 45139 | C33: 0.40972222 | D33: -18.92 | E33: 0.02 | F33: -152.7 | G33: 0.1 | H33: -1.3
A34: Discharge 1.1 | B34: 45140 | C34: 0.68888889
A35: Discharge 1.2 | B35: 45140 | C35: 0.69722222
A36: 19 | B36: 45146 | C36: 0.4375 | D36: -18.88 | E36: 0.015 | F36: -151.8 | G36: 0.2 | H36: -0.7
A37: Discharge 2.1 | B37: 45149 | C37: 0.63472222
A38: Discharge 2.2 | B38: 45149 | C38: 0.6375
A39: Discharge 2.3 | B39: 45149 | C39: 0.65416667
A40: Discharge 2.4 | B40: 45149 | C40: 0.65833333
...

Sheet POC_full

Sheet DUCCEM_full_CDOM
